<?xml version="1.0" encoding="utf-8"?>
<!-- This URDF was automatically created by SolidWorks to URDF Exporter! Originally created by Stephen Brawner (brawner@gmail.com) 
     Commit Version: 1.6.0-4-g7f85cfe  Build Version: 1.6.7995.38578
     For more information, please see http://wiki.ros.org/sw_urdf_exporter -->
<robot
  name="ditto_2f_leader">
  <link
    name="base_link">
    <inertial>
      <origin
        xyz="-0.0167215910487642 -0.0424176198266553 0.0114046398235692"
        rpy="0 0 0" />
      <mass
        value="0.0870719662910429" />
      <inertia
        ixx="3.85466823750408E-05"
        ixy="-1.34266179845903E-06"
        ixz="4.26428735745321E-06"
        iyy="3.34272840543675E-05"
        iyz="-1.03646744741951E-06"
        izz="5.3570981699147E-05" />
    </inertial>
    <visual>
      <origin
        xyz="0 0 0"
        rpy="0 0 0" />
      <geometry>
        <mesh
          filename="meshes/base_link.STL" />
      </geometry>
      <material
        name="">
        <color
          rgba="0.250980392156863 0.250980392156863 0.250980392156863 1" />
      </material>
    </visual>
    <collision>
      <origin
        xyz="0 0 0"
        rpy="0 0 0" />
      <geometry>
        <mesh
          filename="meshes/base_link.STL" />
      </geometry>
    </collision>
  </link>
  <link
    name="index_link_0">
    <inertial>
      <origin
        xyz="0.0271735386977429 3.02693931357674E-09 0.0290057238790129"
        rpy="0 0 0" />
      <mass
        value="0.0234290807402588" />
      <inertia
        ixx="3.11468553842293E-06"
        ixy="-1.63639516318463E-13"
        ixz="-2.1506879881659E-07"
        iyy="3.56962661403034E-06"
        iyz="-2.93292357401665E-13"
        izz="1.91839577955842E-06" />
    </inertial>
    <visual>
      <origin
        xyz="0 0 0"
        rpy="0 0 0" />
      <geometry>
        <mesh
          filename="meshes/index_link_0.STL" />
      </geometry>
      <material
        name="">
        <color
          rgba="0.250980392156863 0.250980392156863 0.250980392156863 1" />
      </material>
    </visual>
    <collision>
      <origin
        xyz="0 0 0"
        rpy="0 0 0" />
      <geometry>
        <mesh
          filename="meshes/index_link_0.STL" />
      </geometry>
    </collision>
  </link>
  <joint
    name="index_joint_0"
    type="revolute">
    <origin
      xyz="0 0 0"
      rpy="0 0 0" />
    <parent
      link="base_link" />
    <child
      link="index_link_0" />
    <axis
      xyz="0 0 1" />
    <limit
      lower="-0.3"
      upper="0.8"
      effort="0"
      velocity="0" />
  </joint>
  <link name="retarget_base">
    <inertial>
      <origin xyz="0 0 0" rpy="0 0 0" />
      <mass value="1.0E-06" />
      <inertia ixx="1.0E-12" ixy="0" ixz="0" iyy="1.0E-12" iyz="0" izz="1.0E-12" />
    </inertial>
  </link>
  <joint name="retarget_base_joint" type="fixed">
    <origin xyz="0 0 0.046" rpy="0 0 0" />
    <parent link="base_link" />
    <child link="retarget_base" />
  </joint>
  <link
    name="index_link_1">
    <inertial>
      <origin
        xyz="0.0324867258156198 -0.00549943022495447 0.000209333565141162"
        rpy="0 0 0" />
      <mass
        value="0.0277581841607585" />
      <inertia
        ixx="4.11454234312938E-06"
        ixy="4.96840161489648E-08"
        ixz="1.58829402913686E-13"
        iyy="2.57034877332712E-06"
        iyz="-4.28535395323684E-08"
        izz="2.91638603075459E-06" />
    </inertial>
    <visual>
      <origin
        xyz="0 0 0"
        rpy="0 0 0" />
      <geometry>
        <mesh
          filename="meshes/index_link_1.STL" />
      </geometry>
      <material
        name="">
        <color
          rgba="0.250980392156863 0.250980392156863 0.250980392156863 1" />
      </material>
    </visual>
    <collision>
      <origin
        xyz="0 0 0"
        rpy="0 0 0" />
      <geometry>
        <mesh
          filename="meshes/index_link_1.STL" />
      </geometry>
    </collision>
  </link>
  <joint
    name="index_joint_1"
    type="revolute">
    <origin
      xyz="0.03 0 0.046"
      rpy="1.5707963267949 0 1.57079632679489" />
    <parent
      link="index_link_0" />
    <child
      link="index_link_1" />
    <axis
      xyz="0 0 1" />
    <limit
      lower="-0.17"
      upper="1.57"
      effort="0"
      velocity="0" />
  </joint>
  <link
    name="index_link_2">
    <inertial>
      <origin
        xyz="0.0100768333002347 1.60811422317891E-13 -1.20250664915601E-12"
        rpy="0 0 0" />
      <mass
        value="0.00252674876938613" />
      <inertia
        ixx="5.37570168949988E-07"
        ixy="2.36900740850728E-18"
        ixz="-2.6858201609854E-17"
        iyy="5.77184540925893E-07"
        iyz="2.72601827020438E-18"
        izz="2.1332062555457E-07" />
    </inertial>
    <visual>
      <origin
        xyz="0 0 0"
        rpy="0 0 0" />
      <geometry>
        <mesh
          filename="meshes/index_link_2.STL" />
      </geometry>
      <material
        name="">
        <color
          rgba="0.250980392156863 0.250980392156863 0.250980392156863 1" />
      </material>
    </visual>
    <collision>
      <origin
        xyz="0 0 0"
        rpy="0 0 0" />
      <geometry>
        <mesh
          filename="meshes/index_link_2.STL" />
      </geometry>
    </collision>
  </link>
  <joint
    name="index_joint_2"
    type="revolute">
    <origin
      xyz="0.0409999999999936 0 0"
      rpy="0 0 0" />
    <parent
      link="index_link_1" />
    <child
      link="index_link_2" />
    <axis
      xyz="0 0 1" />
    <limit
      lower="-0.1"
      upper="1.57"
      effort="0"
      velocity="0" />
  </joint>
  <link
    name="index_fingerpad">
    <inertial>
      <origin
        xyz="-0.0143776168738558 -0.0023750894536163 -0.00159388581260678"
        rpy="0 0 0" />
      <mass
        value="0.00293503442151317" />
      <inertia
        ixx="1.33921402324697E-07"
        ixy="-4.95796402224682E-08"
        ixz="-3.54546585025201E-08"
        iyy="3.38297009689615E-07"
        iyz="-3.08234184419314E-08"
        izz="3.77300622282155E-07" />
    </inertial>
    <visual>
      <origin
        xyz="0 0 0"
        rpy="0 0 0" />
      <geometry>
        <mesh
          filename="meshes/index_fingerpad.STL" />
      </geometry>
      <material
        name="">
        <color
          rgba="0.250980392156863 0.250980392156863 0.250980392156863 1" />
      </material>
    </visual>
    <collision>
      <origin
        xyz="0 0 0"
        rpy="0 0 0" />
      <geometry>
        <mesh
          filename="meshes/index_fingerpad.STL" />
      </geometry>
    </collision>
  </link>
  <joint
    name="index_fingerpad_joint"
    type="fixed">
    <origin
      xyz="0.0322000000000001 0.00700000000000183 -0.0278000000000001"
      rpy="-1.5707963267949 0 0" />
    <parent
      link="index_link_2" />
    <child
      link="index_fingerpad" />
    <axis
      xyz="0 0 0" />
  </joint>
  <link
    name="thumb_link_0">
    <inertial>
      <origin
        xyz="0.027721140491236 0.0124445544239226 0.0455118929556209"
        rpy="0 0 0" />
      <mass
        value="0.0360287572495203" />
      <inertia
        ixx="1.75150293312772E-05"
        ixy="-3.4941761783558E-07"
        ixz="-5.69771563106504E-06"
        iyy="1.93710255768995E-05"
        iyz="5.46256846149743E-07"
        izz="5.97339197497643E-06" />
    </inertial>
    <visual>
      <origin
        xyz="0 0 0"
        rpy="0 0 0" />
      <geometry>
        <mesh
          filename="meshes/thumb_link_0.STL" />
      </geometry>
      <material
        name="">
        <color
          rgba="0.250980392156863 0.250980392156863 0.250980392156863 1" />
      </material>
    </visual>
    <collision>
      <origin
        xyz="0 0 0"
        rpy="0 0 0" />
      <geometry>
        <mesh
          filename="meshes/thumb_link_0.STL" />
      </geometry>
    </collision>
  </link>
  <joint
    name="thumb_joint_0"
    type="revolute">
    <origin
      xyz="-0.0021417 -0.080436 0.0054795"
      rpy="0.016838 -0.18167 -1.6637" />
    <parent
      link="base_link" />
    <child
      link="thumb_link_0" />
    <axis
      xyz="0 -0.16711 0.98594" />
    <limit
      lower="-0.57"
      upper="0.8"
      effort="0"
      velocity="0" />
  </joint>
  <link
    name="thumb_link_1">
    <inertial>
      <origin
        xyz="0.0415651938691397 0.0230648362829694 -0.0135230722742167"
        rpy="0 0 0" />
      <mass
        value="0.0337789978005483" />
      <inertia
        ixx="4.61511916267369E-06"
        ixy="-1.59805595804912E-06"
        ixz="7.95780644293982E-07"
        iyy="6.53418176403598E-06"
        iyz="6.17483182179751E-08"
        izz="5.66157678825439E-06" />
    </inertial>
    <visual>
      <origin
        xyz="0 0 0"
        rpy="0 0 0" />
      <geometry>
        <mesh
          filename="meshes/thumb_link_1.STL" />
      </geometry>
      <material
        name="">
        <color
          rgba="0.250980392156863 0.250980392156863 0.250980392156863 1" />
      </material>
    </visual>
    <collision>
      <origin
        xyz="0 0 0"
        rpy="0 0 0" />
      <geometry>
        <mesh
          filename="meshes/thumb_link_1.STL" />
      </geometry>
    </collision>
  </link>
  <joint
    name="thumb_joint_1"
    type="revolute">
    <origin
      xyz="0.033941 0.023014 0.067326"
      rpy="1.4005 -0.79917 2.4717" />
    <parent
      link="thumb_link_0" />
    <child
      link="thumb_link_1" />
    <axis
      xyz="0 0 1" />
    <limit
      lower="-1.57"
      upper="0.3"
      effort="0"
      velocity="0" />
  </joint>
  <link
    name="thumb_link_2">
    <inertial>
      <origin
        xyz="0.0292947393624981 0.00579498422914698 -0.00775278692823329"
        rpy="0 0 0" />
      <mass
        value="0.0235045649917366" />
      <inertia
        ixx="3.56323789548824E-06"
        ixy="-1.01749709931018E-08"
        ixz="1.29053119280498E-16"
        iyy="2.18948897180294E-06"
        iyz="4.28549417449362E-08"
        izz="2.60810652101685E-06" />
    </inertial>
    <visual>
      <origin
        xyz="0 0 0"
        rpy="0 0 0" />
      <geometry>
        <mesh
          filename="meshes/thumb_link_2.STL" />
      </geometry>
      <material
        name="">
        <color
          rgba="0.250980392156863 0.250980392156863 0.250980392156863 1" />
      </material>
    </visual>
    <collision>
      <origin
        xyz="0 0 0"
        rpy="0 0 0" />
      <geometry>
        <mesh
          filename="meshes/thumb_link_2.STL" />
      </geometry>
    </collision>
  </link>
  <joint
    name="thumb_joint_2"
    type="revolute">
    <origin
      xyz="0.0592471988937204 0.0378393192831767 -0.019789507993749"
      rpy="1.14448873095508 0.194946179240087 1.71050085923731" />
    <parent
      link="thumb_link_1" />
    <child
      link="thumb_link_2" />
    <axis
      xyz="0 0 1" />
    <limit
      lower="-1.57"
      upper="0.3"
      effort="0"
      velocity="0" />
  </joint>
  <link
    name="thumb_link_3">
    <inertial>
      <origin
        xyz="0.0100768331773071 -5.45364933768333E-11 -0.00799999996804439"
        rpy="0 0 0" />
      <mass
        value="0.00252674889330345" />
      <inertia
        ixx="5.37570170098015E-07"
        ixy="-5.88779755094402E-16"
        ixz="3.81324993246444E-16"
        iyy="5.77184541773845E-07"
        iyz="-3.88279274364106E-17"
        izz="2.13320626356563E-07" />
    </inertial>
    <visual>
      <origin
        xyz="0 0 0"
        rpy="0 0 0" />
      <geometry>
        <mesh
          filename="meshes/thumb_link_3.STL" />
      </geometry>
      <material
        name="">
        <color
          rgba="0.250980392156863 0.250980392156863 0.250980392156863 1" />
      </material>
    </visual>
    <collision>
      <origin
        xyz="0 0 0"
        rpy="0 0 0" />
      <geometry>
        <mesh
          filename="meshes/thumb_link_3.STL" />
      </geometry>
    </collision>
  </link>
  <joint
    name="thumb_joint_3"
    type="revolute">
    <origin
      xyz="0.035 0 0"
      rpy="0 0 0" />
    <parent
      link="thumb_link_2" />
    <child
      link="thumb_link_3" />
    <axis
      xyz="0 0 1" />
    <limit
      lower="-1.57"
      upper="0.1"
      effort="0"
      velocity="0" />
  </joint>
  <link
    name="thumb_fingerpad">
    <inertial>
      <origin
        xyz="-0.00844009736991905 0.00573387152339499 -0.00521265550446395"
        rpy="0 0 0" />
      <mass
        value="0.00282848549611835" />
      <inertia
        ixx="2.9190702938091E-07"
        ixy="9.70880291218955E-09"
        ixz="9.150794182762E-09"
        iyy="2.36829249448183E-07"
        iyz="8.34407283628955E-08"
        izz="1.71632993338816E-07" />
    </inertial>
    <visual>
      <origin
        xyz="0 0 0"
        rpy="0 0 0" />
      <geometry>
        <mesh
          filename="meshes/thumb_fingerpad.STL" />
      </geometry>
      <material
        name="">
        <color
          rgba="0.250980392156863 0.250980392156863 0.250980392156863 1" />
      </material>
    </visual>
    <collision>
      <origin
        xyz="0 0 0"
        rpy="0 0 0" />
      <geometry>
        <mesh
          filename="meshes/thumb_fingerpad.STL" />
      </geometry>
    </collision>
  </link>
  <joint
    name="thumb_fingerpad_joint"
    type="fixed">
    <origin
      xyz="0.0340000000000001 -0.00500000000000015 -0.0398000000000016"
      rpy="1.80666825946075 -0.379498136323909 0.503100653479423" />
    <parent
      link="thumb_link_3" />
    <child
      link="thumb_fingerpad" />
    <axis
      xyz="0 0 0" />
  </joint>
</robot>