<?xml version="1.0" encoding="utf-8"?>
<!-- This URDF was automatically created by SolidWorks to URDF Exporter! Originally created by Stephen Brawner (brawner@gmail.com) 
     Commit Version: 1.6.0-4-g7f85cfe  Build Version: 1.6.7995.38578
     For more information, please see http://wiki.ros.org/sw_urdf_exporter -->
<robot
  name="ditto_3f_leader">
  <link
    name="base_link">
    <inertial>
      <origin
        xyz="-0.0213561328356412 -0.0366253635659899 0.00973470669305248"
        rpy="0 0 0" />
      <mass
        value="0.109125547143221" />
      <inertia
        ixx="4.18384967301601E-05"
        ixy="-1.3641439625342E-06"
        ixz="4.29400345729265E-06"
        iyy="3.55799228843054E-05"
        iyz="-8.34201252822404E-07"
        izz="5.61288584240305E-05" />
    </inertial>
    <visual>
      <origin
        xyz="0 0 0"
        rpy="0 0 0" />
      <geometry>
        <mesh
          filename="meshes/base_link.STL" />
      </geometry>
      <material
        name="">
        <color
          rgba="0.250980392156863 0.250980392156863 0.250980392156863 1" />
      </material>
    </visual>
    <collision>
      <origin
        xyz="0 0 0"
        rpy="0 0 0" />
      <geometry>
        <mesh
          filename="meshes/base_link.STL" />
      </geometry>
    </collision>
  </link>
  <link
    name="index_link_0">
    <inertial>
      <origin
        xyz="0.0271735386977429 3.02693931369142E-09 0.0290057238790129"
        rpy="0 0 0" />
      <mass
        value="0.0234290807402588" />
      <inertia
        ixx="3.11468553842293E-06"
        ixy="-1.63639516312443E-13"
        ixz="-2.1506879881659E-07"
        iyy="3.56962661403034E-06"
        iyz="-2.93292357355132E-13"
        izz="1.91839577955842E-06" />
    </inertial>
    <visual>
      <origin
        xyz="0 0 0"
        rpy="0 0 0" />
      <geometry>
        <mesh
          filename="meshes/index_link_0.STL" />
      </geometry>
      <material
        name="">
        <color
          rgba="0.250980392156863 0.250980392156863 0.250980392156863 1" />
      </material>
    </visual>
    <collision>
      <origin
        xyz="0 0 0"
        rpy="0 0 0" />
      <geometry>
        <mesh
          filename="meshes/index_link_0.STL" />
      </geometry>
    </collision>
  </link>
  <joint
    name="index_joint_0"
    type="revolute">
    <origin
      xyz="0 0 0"
      rpy="0 0 0" />
    <parent
      link="base_link" />
    <child
      link="index_link_0" />
    <axis
      xyz="0 0 -1" />
    <limit
      lower="-0.8"
      upper="0.3"
      effort="0"
      velocity="0" />
  </joint>
  <link name="retarget_base">
    <inertial>
      <origin xyz="0 0 0" rpy="0 0 0" />
      <mass value="1.0E-06" />
      <inertia ixx="1.0E-12" ixy="0" ixz="0" iyy="1.0E-12" iyz="0" izz="1.0E-12" />
    </inertial>
  </link>
  <joint name="retarget_base_joint" type="fixed">
    <origin xyz="0 0 0.046" rpy="0 0 0" />
    <parent link="base_link" />
    <child link="retarget_base" />
  </joint>
  <link
    name="index_link_1">
    <inertial>
      <origin
        xyz="0.0324867258156198 -0.00549943022495447 0.000209333565141162"
        rpy="0 0 0" />
      <mass
        value="0.0277581841607585" />
      <inertia
        ixx="4.11454234312938E-06"
        ixy="4.96840161489649E-08"
        ixz="1.58829402867338E-13"
        iyy="2.57034877332712E-06"
        iyz="-4.28535395323684E-08"
        izz="2.91638603075459E-06" />
    </inertial>
    <visual>
      <origin
        xyz="0 0 0"
        rpy="0 0 0" />
      <geometry>
        <mesh
          filename="meshes/index_link_1.STL" />
      </geometry>
      <material
        name="">
        <color
          rgba="0.250980392156863 0.250980392156863 0.250980392156863 1" />
      </material>
    </visual>
    <collision>
      <origin
        xyz="0 0 0"
        rpy="0 0 0" />
      <geometry>
        <mesh
          filename="meshes/index_link_1.STL" />
      </geometry>
    </collision>
  </link>
  <joint
    name="index_joint_1"
    type="revolute">
    <origin
      xyz="0.03 0 0.046"
      rpy="1.5707963267949 0 1.57079632679489" />
    <parent
      link="index_link_0" />
    <child
      link="index_link_1" />
    <axis
      xyz="0 0 -1" />
    <limit
      lower="-1.57"
      upper="0.17"
      effort="0"
      velocity="0" />
  </joint>
  <link
    name="index_link_2">
    <inertial>
      <origin
        xyz="0.0100768333002347 1.60820712605955E-13 -1.20264999675168E-12"
        rpy="0 0 0" />
      <mass
        value="0.00252674876938613" />
      <inertia
        ixx="5.37570168949988E-07"
        ixy="2.3690052303945E-18"
        ixz="-2.68581997503519E-17"
        iyy="5.77184540925893E-07"
        iyz="2.72601460923019E-18"
        izz="2.1332062555457E-07" />
    </inertial>
    <visual>
      <origin
        xyz="0 0 0"
        rpy="0 0 0" />
      <geometry>
        <mesh
          filename="meshes/index_link_2.STL" />
      </geometry>
      <material
        name="">
        <color
          rgba="0.250980392156863 0.250980392156863 0.250980392156863 1" />
      </material>
    </visual>
    <collision>
      <origin
        xyz="0 0 0"
        rpy="0 0 0" />
      <geometry>
        <mesh
          filename="meshes/index_link_2.STL" />
      </geometry>
    </collision>
  </link>
  <joint
    name="index_joint_2"
    type="revolute">
    <origin
      xyz="0.0409999999999935 0 0"
      rpy="0 0 0" />
    <parent
      link="index_link_1" />
    <child
      link="index_link_2" />
    <axis
      xyz="0 0 -1" />
    <limit
      lower="-1.57"
      upper="0.1"
      effort="0"
      velocity="0" />
  </joint>
  <link
    name="index_fingerpad">
    <inertial>
      <origin
        xyz="-0.0143776168752036 -0.00237508945353907 -0.00159388581233799"
        rpy="0 0 0" />
      <mass
        value="0.00293503442078024" />
      <inertia
        ixx="1.33921402320109E-07"
        ixy="-4.95796402223525E-08"
        ixz="-3.5454658506907E-08"
        iyy="3.38297009665592E-07"
        iyz="-3.08234184419248E-08"
        izz="3.77300622257017E-07" />
    </inertial>
    <visual>
      <origin
        xyz="0 0 0"
        rpy="0 0 0" />
      <geometry>
        <mesh
          filename="meshes/index_fingerpad.STL" />
      </geometry>
      <material
        name="">
        <color
          rgba="0.250980392156863 0.250980392156863 0.250980392156863 1" />
      </material>
    </visual>
    <collision>
      <origin
        xyz="0 0 0"
        rpy="0 0 0" />
      <geometry>
        <mesh
          filename="meshes/index_fingerpad.STL" />
      </geometry>
    </collision>
  </link>
  <joint
    name="index_fingerpad_joint"
    type="fixed">
    <origin
      xyz="0.0322000000000001 0.00700000000000183 -0.0278000000000001"
      rpy="-1.5707963267949 0 0" />
    <parent
      link="index_link_2" />
    <child
      link="index_fingerpad" />
    <axis
      xyz="0 0 0" />
  </joint>
  <link
    name="thumb_link_0">
    <inertial>
      <origin
        xyz="0.027721140491236 0.0124445544239226 0.0455118929556209"
        rpy="0 0 0" />
      <mass
        value="0.0360287572495203" />
      <inertia
        ixx="1.75150293312771E-05"
        ixy="-3.49417617835589E-07"
        ixz="-5.69771563106498E-06"
        iyy="1.93710255768993E-05"
        iyz="5.46256846149709E-07"
        izz="5.97339197497642E-06" />
    </inertial>
    <visual>
      <origin
        xyz="0 0 0"
        rpy="0 0 0" />
      <geometry>
        <mesh
          filename="meshes/thumb_link_0.STL" />
      </geometry>
      <material
        name="">
        <color
          rgba="0.250980392156863 0.250980392156863 0.250980392156863 1" />
      </material>
    </visual>
    <collision>
      <origin
        xyz="0 0 0"
        rpy="0 0 0" />
      <geometry>
        <mesh
          filename="meshes/thumb_link_0.STL" />
      </geometry>
    </collision>
  </link>
  <joint
    name="thumb_joint_0"
    type="revolute">
    <origin
      xyz="-0.00214172528372005 -0.0804363017815774 0.00547954198946005"
      rpy="0.016838154197939 -0.181665966850915 -1.66373584590886" />
    <parent
      link="base_link" />
    <child
      link="thumb_link_0" />
    <axis
      xyz="0 -0.167114290573186 0.985937530417734" />
    <limit
      lower="-0.57"
      upper="0.8"
      effort="0"
      velocity="0" />
  </joint>
  <link
    name="thumb_link_1">
    <inertial>
      <origin
        xyz="0.0415651938691396 0.0230648362829693 -0.0135230722742165"
        rpy="0 0 0" />
      <mass
        value="0.0337789978005482" />
      <inertia
        ixx="4.61511916267369E-06"
        ixy="-1.59805595804912E-06"
        ixz="7.95780644293983E-07"
        iyy="6.53418176403598E-06"
        iyz="6.17483182179756E-08"
        izz="5.66157678825438E-06" />
    </inertial>
    <visual>
      <origin
        xyz="0 0 0"
        rpy="0 0 0" />
      <geometry>
        <mesh
          filename="meshes/thumb_link_1.STL" />
      </geometry>
      <material
        name="">
        <color
          rgba="0.250980392156863 0.250980392156863 0.250980392156863 1" />
      </material>
    </visual>
    <collision>
      <origin
        xyz="0 0 0"
        rpy="0 0 0" />
      <geometry>
        <mesh
          filename="meshes/thumb_link_1.STL" />
      </geometry>
    </collision>
  </link>
  <joint
    name="thumb_joint_1"
    type="revolute">
    <origin
      xyz="0.0339411254969603 0.023013567589507 0.0673262918632758"
      rpy="1.40051047580421 -0.799169731618551 2.47174579176664" />
    <parent
      link="thumb_link_0" />
    <child
      link="thumb_link_1" />
    <axis
      xyz="0 0 1" />
    <limit
      lower="-1.57"
      upper="0.3"
      effort="0"
      velocity="0" />
  </joint>
  <link
    name="thumb_link_2">
    <inertial>
      <origin
        xyz="0.0292947393624981 0.00579498422914695 -0.00775278692823328"
        rpy="0 0 0" />
      <mass
        value="0.0235045649917366" />
      <inertia
        ixx="3.56323789548823E-06"
        ixy="-1.01749709931021E-08"
        ixz="1.29052781790808E-16"
        iyy="2.18948897180294E-06"
        iyz="4.2854941744936E-08"
        izz="2.60810652101685E-06" />
    </inertial>
    <visual>
      <origin
        xyz="0 0 0"
        rpy="0 0 0" />
      <geometry>
        <mesh
          filename="meshes/thumb_link_2.STL" />
      </geometry>
      <material
        name="">
        <color
          rgba="0.250980392156863 0.250980392156863 0.250980392156863 1" />
      </material>
    </visual>
    <collision>
      <origin
        xyz="0 0 0"
        rpy="0 0 0" />
      <geometry>
        <mesh
          filename="meshes/thumb_link_2.STL" />
      </geometry>
    </collision>
  </link>
  <joint
    name="thumb_joint_2"
    type="revolute">
    <origin
      xyz="0.0592471988937203 0.0378393192831765 -0.0197895079937487"
      rpy="1.14448873095508 0.194946179240088 1.71050085923731" />
    <parent
      link="thumb_link_1" />
    <child
      link="thumb_link_2" />
    <axis
      xyz="0 0 1" />
    <limit
      lower="-1.57"
      upper="0.3"
      effort="0"
      velocity="0" />
  </joint>
  <link
    name="thumb_link_3">
    <inertial>
      <origin
        xyz="0.0100768331773071 -5.45364933768333E-11 -0.00799999996804443"
        rpy="0 0 0" />
      <mass
        value="0.00252674889330346" />
      <inertia
        ixx="5.37570170098016E-07"
        ixy="-5.88779675685063E-16"
        ixz="3.81325110706091E-16"
        iyy="5.77184541773846E-07"
        iyz="-3.88278447183493E-17"
        izz="2.13320626356563E-07" />
    </inertial>
    <visual>
      <origin
        xyz="0 0 0"
        rpy="0 0 0" />
      <geometry>
        <mesh
          filename="meshes/thumb_link_3.STL" />
      </geometry>
      <material
        name="">
        <color
          rgba="0.250980392156863 0.250980392156863 0.250980392156863 1" />
      </material>
    </visual>
    <collision>
      <origin
        xyz="0 0 0"
        rpy="0 0 0" />
      <geometry>
        <mesh
          filename="meshes/thumb_link_3.STL" />
      </geometry>
    </collision>
  </link>
  <joint
    name="thumb_joint_3"
    type="revolute">
    <origin
      xyz="0.035 0 0"
      rpy="0 0 0" />
    <parent
      link="thumb_link_2" />
    <child
      link="thumb_link_3" />
    <axis
      xyz="0 0 1" />
    <limit
      lower="-1.57"
      upper="0.1"
      effort="0"
      velocity="0" />
  </joint>
  <link
    name="thumb_fingerpad">
    <inertial>
      <origin
        xyz="-0.00844009736991974 0.00573387152339363 -0.00521265550446311"
        rpy="0 0 0" />
      <mass
        value="0.00282848549611836" />
      <inertia
        ixx="2.9190702938092E-07"
        ixy="9.70880291220612E-09"
        ixz="9.1507941828543E-09"
        iyy="2.36829249448083E-07"
        iyz="8.34407283629399E-08"
        izz="1.71632993338662E-07" />
    </inertial>
    <visual>
      <origin
        xyz="0 0 0"
        rpy="0 0 0" />
      <geometry>
        <mesh
          filename="meshes/thumb_fingerpad.STL" />
      </geometry>
      <material
        name="">
        <color
          rgba="0.250980392156863 0.250980392156863 0.250980392156863 1" />
      </material>
    </visual>
    <collision>
      <origin
        xyz="0 0 0"
        rpy="0 0 0" />
      <geometry>
        <mesh
          filename="meshes/thumb_fingerpad.STL" />
      </geometry>
    </collision>
  </link>
  <joint
    name="thumb_fingerpad_joint"
    type="fixed">
    <origin
      xyz="0.034 -0.00499999999999969 -0.0398"
      rpy="1.80666825946076 -0.379498136323909 0.503100653479423" />
    <parent
      link="thumb_link_3" />
    <child
      link="thumb_fingerpad" />
    <axis
      xyz="0 0 0" />
  </joint>
  <link
    name="middle_link_0">
    <inertial>
      <origin
        xyz="0.0428660995746774 -6.81652114744788E-10 0.0275129733864136"
        rpy="0 0 0" />
      <mass
        value="0.0257036203076206" />
      <inertia
        ixx="3.37340622109194E-06"
        ixy="-4.6810213020141E-14"
        ixz="-4.65928978802705E-07"
        iyy="4.87334238776261E-06"
        iyz="-1.17575733298302E-13"
        izz="3.10117177028274E-06" />
    </inertial>
    <visual>
      <origin
        xyz="0 0 0"
        rpy="0 0 0" />
      <geometry>
        <mesh
          filename="meshes/middle_link_0.STL" />
      </geometry>
      <material
        name="">
        <color
          rgba="0.250980392156863 0.250980392156863 0.250980392156863 1" />
      </material>
    </visual>
    <collision>
      <origin
        xyz="0 0 0"
        rpy="0 0 0" />
      <geometry>
        <mesh
          filename="meshes/middle_link_0.STL" />
      </geometry>
    </collision>
  </link>
  <joint
    name="middle_joint_0"
    type="revolute">
    <origin
      xyz="-0.0395 0.0005 0"
      rpy="0 0 3.1416" />
    <parent
      link="base_link" />
    <child
      link="middle_link_0" />
    <axis
      xyz="0 0 -1" />
    <limit
      lower="-0.3"
      upper="0.3"
      effort="0"
      velocity="0" />
  </joint>
  <link
    name="middle_link_1">
    <inertial>
      <origin
        xyz="0.0364928103809854 -0.00525061406363379 0.000176615436499439"
        rpy="0 0 0" />
      <mass
        value="0.0329000270028115" />
      <inertia
        ixx="4.78314507668699E-06"
        ixy="1.40869805443594E-07"
        ixz="-3.79420138484226E-14"
        iyy="3.23635026567844E-06"
        iyz="-4.28547769247268E-08"
        izz="3.4883400552915E-06" />
    </inertial>
    <visual>
      <origin
        xyz="0 0 0"
        rpy="0 0 0" />
      <geometry>
        <mesh
          filename="meshes/middle_link_1.STL" />
      </geometry>
      <material
        name="">
        <color
          rgba="0.250980392156863 0.250980392156863 0.250980392156863 1" />
      </material>
    </visual>
    <collision>
      <origin
        xyz="0 0 0"
        rpy="0 0 0" />
      <geometry>
        <mesh
          filename="meshes/middle_link_1.STL" />
      </geometry>
    </collision>
  </link>
  <joint
    name="middle_joint_1"
    type="revolute">
    <origin
      xyz="0.052 0 0.046"
      rpy="1.5708 0 -1.5708" />
    <parent
      link="middle_link_0" />
    <child
      link="middle_link_1" />
    <axis
      xyz="0 0 -1" />
    <limit
      lower="-1.57"
      upper="0.17"
      effort="0"
      velocity="0" />
  </joint>
  <link
    name="middle_link_2">
    <inertial>
      <origin
        xyz="0.0100768333002347 1.60802726857313E-13 -1.20251031354712E-12"
        rpy="0 0 0" />
      <mass
        value="0.00252674876938613" />
      <inertia
        ixx="5.37570168949986E-07"
        ixy="2.36895988529726E-18"
        ixz="-2.68580671741651E-17"
        iyy="5.7718454092589E-07"
        iyz="2.72609273625266E-18"
        izz="2.13320625554569E-07" />
    </inertial>
    <visual>
      <origin
        xyz="0 0 0"
        rpy="0 0 0" />
      <geometry>
        <mesh
          filename="meshes/middle_link_2.STL" />
      </geometry>
      <material
        name="">
        <color
          rgba="0.250980392156863 0.250980392156863 0.250980392156863 1" />
      </material>
    </visual>
    <collision>
      <origin
        xyz="0 0 0"
        rpy="0 0 0" />
      <geometry>
        <mesh
          filename="meshes/middle_link_2.STL" />
      </geometry>
    </collision>
  </link>
  <joint
    name="middle_joint_2"
    type="revolute">
    <origin
      xyz="0.0485 0 0"
      rpy="0 0 0" />
    <parent
      link="middle_link_1" />
    <child
      link="middle_link_2" />
    <axis
      xyz="0 0 -1" />
    <limit
      lower="-1.57"
      upper="0.1"
      effort="0"
      velocity="0" />
  </joint>
  <link
    name="middle_fingerpad">
    <inertial>
      <origin
        xyz="-0.0114172280277434 0.0227073491989478 -0.00166305516375729"
        rpy="0 0 0" />
      <mass
        value="0.00354844692145956" />
      <inertia
        ixx="1.7009250350319E-06"
        ixy="5.17333400765718E-07"
        ixz="-5.44575449393752E-08"
        iyy="3.42334541322453E-07"
        iyz="1.83444166080006E-07"
        izz="1.89160731311215E-06" />
    </inertial>
    <visual>
      <origin
        xyz="0 0 0"
        rpy="0 0 0" />
      <geometry>
        <mesh
          filename="meshes/middle_fingerpad.STL" />
      </geometry>
      <material
        name="">
        <color
          rgba="0.250980392156863 0.250980392156863 0.250980392156863 1" />
      </material>
    </visual>
    <collision>
      <origin
        xyz="0 0 0"
        rpy="0 0 0" />
      <geometry>
        <mesh
          filename="meshes/middle_fingerpad.STL" />
      </geometry>
    </collision>
  </link>
  <joint
    name="middle_fingerpad_joint"
    type="fixed">
    <origin
      xyz="0.0302000000000001 0.00975000000000249 0.0702999999999999"
      rpy="-1.5707963267949 0 0" />
    <parent
      link="middle_link_2" />
    <child
      link="middle_fingerpad" />
    <axis
      xyz="0 0 0" />
  </joint>
</robot>