<?xml version="1.0" encoding="utf-8"?>
<!-- This URDF was automatically created by SolidWorks to URDF Exporter! Originally created by Stephen Brawner (brawner@gmail.com) 
     Commit Version: 1.6.0-4-g7f85cfe  Build Version: 1.6.7995.38578
     For more information, please see http://wiki.ros.org/sw_urdf_exporter -->
<robot
  name="ditto_3f_leader">
  <link
    name="base_link">
    <inertial>
      <origin
        xyz="-0.0175245807545887 -0.0393052235247903 0.00988025352563784"
        rpy="0 0 0" />
      <mass
        value="0.104263737833624" />
      <inertia
        ixx="3.55911062152398E-05"
        ixy="1.21340169205844E-06"
        ixz="3.57662576703752E-06"
        iyy="3.21856459633448E-05"
        iyz="-3.19677163448676E-06"
        izz="4.91057778291288E-05" />
    </inertial>
    <visual>
      <origin
        xyz="0 0 0"
        rpy="0 0 0" />
      <geometry>
        <mesh
          filename="meshes/base_link.STL" />
      </geometry>
      <material
        name="">
        <color
          rgba="0.250980392156863 0.250980392156863 0.250980392156863 1" />
      </material>
    </visual>
    <collision>
      <origin
        xyz="0 0 0"
        rpy="0 0 0" />
      <geometry>
        <mesh
          filename="meshes/base_link.STL" />
      </geometry>
    </collision>
  </link>
  <link
    name="index_link_0">
    <inertial>
      <origin
        xyz="0.0271735386977431 3.02693906264153E-09 0.0290057238790127"
        rpy="0 0 0" />
      <mass
        value="0.0234290807402588" />
      <inertia
        ixx="3.11468553842293E-06"
        ixy="-1.63639517838046E-13"
        ixz="-2.1506879881659E-07"
        iyy="3.56962661403034E-06"
        iyz="-2.93292358215524E-13"
        izz="1.91839577955842E-06" />
    </inertial>
    <visual>
      <origin
        xyz="0 0 0"
        rpy="0 0 0" />
      <geometry>
        <mesh
          filename="meshes/index_link_0.STL" />
      </geometry>
      <material
        name="">
        <color
          rgba="0.250980392156863 0.250980392156863 0.250980392156863 1" />
      </material>
    </visual>
    <collision>
      <origin
        xyz="0 0 0"
        rpy="0 0 0" />
      <geometry>
        <mesh
          filename="meshes/index_link_0.STL" />
      </geometry>
    </collision>
  </link>
  <joint
    name="index_joint_0"
    type="revolute">
    <origin
      xyz="0 0 0"
      rpy="0 0 0" />
    <parent
      link="base_link" />
    <child
      link="index_link_0" />
    <axis
      xyz="0 0 1" />
    <limit
      lower="-0.3"
      upper="0.8"
      effort="0"
      velocity="0" />
  </joint>
  <link name="retarget_base">
    <inertial>
      <origin xyz="0 0 0" rpy="0 0 0" />
      <mass value="1.0E-06" />
      <inertia ixx="1.0E-12" ixy="0" ixz="0" iyy="1.0E-12" iyz="0" izz="1.0E-12" />
    </inertial>
  </link>
  <joint name="retarget_base_joint" type="fixed">
    <origin xyz="0 0 0.046" rpy="0 0 0" />
    <parent link="base_link" />
    <child link="retarget_base" />
  </joint>

  <link
    name="index_link_1">
    <inertial>
      <origin
        xyz="0.0324867258156198 -0.00549943022495448 0.000209333565141162"
        rpy="0 0 0" />
      <mass
        value="0.0277581841607585" />
      <inertia
        ixx="4.11454234312938E-06"
        ixy="4.96840161489649E-08"
        ixz="1.5882940287573E-13"
        iyy="2.57034877332712E-06"
        iyz="-4.28535395323684E-08"
        izz="2.91638603075459E-06" />
    </inertial>
    <visual>
      <origin
        xyz="0 0 0"
        rpy="0 0 0" />
      <geometry>
        <mesh
          filename="meshes/index_link_1.STL" />
      </geometry>
      <material
        name="">
        <color
          rgba="0.250980392156863 0.250980392156863 0.250980392156863 1" />
      </material>
    </visual>
    <collision>
      <origin
        xyz="0 0 0"
        rpy="0 0 0" />
      <geometry>
        <mesh
          filename="meshes/index_link_1.STL" />
      </geometry>
    </collision>
  </link>
  <joint
    name="index_joint_1"
    type="revolute">
    <origin
      xyz="0.03 0 0.046"
      rpy="1.5708 0 1.5708" />
    <parent
      link="index_link_0" />
    <child
      link="index_link_1" />
    <axis
      xyz="0 0 1" />
    <limit
      lower="-0.17"
      upper="1.57"
      effort="0"
      velocity="0" />
  </joint>
  <link
    name="index_link_2">
    <inertial>
      <origin
        xyz="0.0100768333002349 1.61102489342299E-13 -1.20279715311857E-12"
        rpy="0 0 0" />
      <mass
        value="0.00252674876938614" />
      <inertia
        ixx="5.37570168949988E-07"
        ixy="2.36899886680455E-18"
        ixz="-2.6858218250309E-17"
        iyy="5.77184540925894E-07"
        iyz="2.72602408903507E-18"
        izz="2.1332062555457E-07" />
    </inertial>
    <visual>
      <origin
        xyz="0 0 0"
        rpy="0 0 0" />
      <geometry>
        <mesh
          filename="meshes/index_link_2.STL" />
      </geometry>
      <material
        name="">
        <color
          rgba="0.250980392156863 0.250980392156863 0.250980392156863 1" />
      </material>
    </visual>
    <collision>
      <origin
        xyz="0 0 0"
        rpy="0 0 0" />
      <geometry>
        <mesh
          filename="meshes/index_link_2.STL" />
      </geometry>
    </collision>
  </link>
  <joint
    name="index_joint_2"
    type="revolute">
    <origin
      xyz="0.041 0 0"
      rpy="0 0 0" />
    <parent
      link="index_link_1" />
    <child
      link="index_link_2" />
    <axis
      xyz="0 0 1" />
    <limit
      lower="-0.1"
      upper="1.57"
      effort="0"
      velocity="0" />
  </joint>
  <link
    name="index_fingerpad">
    <inertial>
      <origin
        xyz="-0.0143776168752033 -0.0023750894535389 -0.0015938858123377"
        rpy="0 0 0" />
      <mass
        value="0.00293503442078025" />
      <inertia
        ixx="1.33921402320109E-07"
        ixy="-4.95796402223535E-08"
        ixz="-3.54546585069071E-08"
        iyy="3.38297009665597E-07"
        iyz="-3.08234184419248E-08"
        izz="3.77300622257022E-07" />
    </inertial>
    <visual>
      <origin
        xyz="0 0 0"
        rpy="0 0 0" />
      <geometry>
        <mesh
          filename="meshes/index_fingerpad.STL" />
      </geometry>
      <material
        name="">
        <color
          rgba="0.250980392156863 0.250980392156863 0.250980392156863 1" />
      </material>
    </visual>
    <collision>
      <origin
        xyz="0 0 0"
        rpy="0 0 0" />
      <geometry>
        <mesh
          filename="meshes/index_fingerpad.STL" />
      </geometry>
    </collision>
  </link>
  <joint
    name="index_fingerpad_joint"
    type="fixed">
    <origin
      xyz="0.0322000000000001 0.00700000000000183 -0.0278000000000001"
      rpy="-1.5707963267949 0 0" />
    <parent
      link="index_link_2" />
    <child
      link="index_fingerpad" />
    <axis
      xyz="0 0 0" />
  </joint>
  <link
    name="thumb_link_0">
    <inertial>
      <origin
        xyz="0.0277211404912801 0.0198752409597919 0.0507922204612535"
        rpy="0 0 0" />
      <mass
        value="0.0360287572495203" />
      <inertia
        ixx="1.75150293312806E-05"
        ixy="-1.29667364879683E-06"
        ixz="-5.55919900099697E-06"
        iyy="1.91768745699568E-05"
        iyz="-1.69170505192384E-06"
        izz="6.16754298188939E-06" />
    </inertial>
    <visual>
      <origin
        xyz="0 0 0"
        rpy="0 0 0" />
      <geometry>
        <mesh
          filename="meshes/thumb_link_0.STL" />
      </geometry>
      <material
        name="">
        <color
          rgba="0.250980392156863 0.250980392156863 0.250980392156863 1" />
      </material>
    </visual>
    <collision>
      <origin
        xyz="0 0 0"
        rpy="0 0 0" />
      <geometry>
        <mesh
          filename="meshes/thumb_link_0.STL" />
      </geometry>
    </collision>
  </link>
  <joint
    name="thumb_joint_0"
    type="revolute">
    <origin
      xyz="-0.00081039 -0.081987 -0.0022549"
      rpy="0.18474 -0.18167 -1.6637" />
    <parent
      link="base_link" />
    <child
      link="thumb_link_0" />
    <axis
      xyz="0 0 1" />
    <limit
      lower="-0.57"
      upper="0.8"
      effort="0"
      velocity="0" />
  </joint>
  <link
    name="thumb_link_1">
    <inertial>
      <origin
        xyz="0.0415651938691134 0.0230648362829999 -0.0135230722741783"
        rpy="0 0 0" />
      <mass
        value="0.0337789978005483" />
      <inertia
        ixx="4.61511916267369E-06"
        ixy="-1.59805595804912E-06"
        ixz="7.95780644293982E-07"
        iyy="6.53418176403598E-06"
        iyz="6.17483182179763E-08"
        izz="5.66157678825438E-06" />
    </inertial>
    <visual>
      <origin
        xyz="0 0 0"
        rpy="0 0 0" />
      <geometry>
        <mesh
          filename="meshes/thumb_link_1.STL" />
      </geometry>
      <material
        name="">
        <color
          rgba="0.250980392156863 0.250980392156863 0.250980392156863 1" />
      </material>
    </visual>
    <collision>
      <origin
        xyz="0 0 0"
        rpy="0 0 0" />
      <geometry>
        <mesh
          filename="meshes/thumb_link_1.STL" />
      </geometry>
    </collision>
  </link>
  <joint
    name="thumb_joint_1"
    type="revolute">
    <origin
      xyz="0.033941 0.033941 0.070534"
      rpy="1.5708 -0.68717 2.3562" />
    <parent
      link="thumb_link_0" />
    <child
      link="thumb_link_1" />
    <axis
      xyz="0 0 1" />
    <limit
      lower="-1.57"
      upper="0.3"
      effort="0"
      velocity="0" />
  </joint>
  <link
    name="thumb_link_2">
    <inertial>
      <origin
        xyz="0.0292947393625432 0.00579498422923298 -0.0077527869282358"
        rpy="0 0 0" />
      <mass
        value="0.0235045649917366" />
      <inertia
        ixx="3.56323789548823E-06"
        ixy="-1.01749709931019E-08"
        ixz="1.2905325824684E-16"
        iyy="2.18948897180294E-06"
        iyz="4.2854941744936E-08"
        izz="2.60810652101685E-06" />
    </inertial>
    <visual>
      <origin
        xyz="0 0 0"
        rpy="0 0 0" />
      <geometry>
        <mesh
          filename="meshes/thumb_link_2.STL" />
      </geometry>
      <material
        name="">
        <color
          rgba="0.250980392156863 0.250980392156863 0.250980392156863 1" />
      </material>
    </visual>
    <collision>
      <origin
        xyz="0 0 0"
        rpy="0 0 0" />
      <geometry>
        <mesh
          filename="meshes/thumb_link_2.STL" />
      </geometry>
    </collision>
  </link>
  <joint
    name="thumb_joint_2"
    type="revolute">
    <origin
      xyz="0.059247 0.037839 -0.01979"
      rpy="1.1445 0.19495 1.7105" />
    <parent
      link="thumb_link_1" />
    <child
      link="thumb_link_2" />
    <axis
      xyz="0 0 1" />
    <limit
      lower="-1.57"
      upper="0.3"
      effort="0"
      velocity="0" />
  </joint>
  <link
    name="thumb_link_3">
    <inertial>
      <origin
        xyz="0.0100768331773522 -5.44504857868944E-11 -0.00799999996804696"
        rpy="0 0 0" />
      <mass
        value="0.00252674889330345" />
      <inertia
        ixx="5.37570170098015E-07"
        ixy="-5.88779748476957E-16"
        ixz="3.81325147929218E-16"
        iyy="5.77184541773845E-07"
        iyz="-3.88280233893616E-17"
        izz="2.13320626356563E-07" />
    </inertial>
    <visual>
      <origin
        xyz="0 0 0"
        rpy="0 0 0" />
      <geometry>
        <mesh
          filename="meshes/thumb_link_3.STL" />
      </geometry>
      <material
        name="">
        <color
          rgba="0.250980392156863 0.250980392156863 0.250980392156863 1" />
      </material>
    </visual>
    <collision>
      <origin
        xyz="0 0 0"
        rpy="0 0 0" />
      <geometry>
        <mesh
          filename="meshes/thumb_link_3.STL" />
      </geometry>
    </collision>
  </link>
  <joint
    name="thumb_joint_3"
    type="revolute">
    <origin
      xyz="0.035 0 0"
      rpy="0 0 0" />
    <parent
      link="thumb_link_2" />
    <child
      link="thumb_link_3" />
    <axis
      xyz="0 0 1" />
    <limit
      lower="-1.57"
      upper="0.1"
      effort="0"
      velocity="0" />
  </joint>
  <link
    name="thumb_fingerpad">
    <inertial>
      <origin
        xyz="-0.00844009736984486 0.00573387152335093 -0.00521265550450817"
        rpy="0 0 0" />
      <mass
        value="0.00282848549611836" />
      <inertia
        ixx="2.91907029380799E-07"
        ixy="9.70880291213006E-09"
        ixz="9.15079418284593E-09"
        iyy="2.36829249448162E-07"
        iyz="8.34407283628755E-08"
        izz="1.71632993338766E-07" />
    </inertial>
    <visual>
      <origin
        xyz="0 0 0"
        rpy="0 0 0" />
      <geometry>
        <mesh
          filename="meshes/thumb_fingerpad.STL" />
      </geometry>
      <material
        name="">
        <color
          rgba="0.250980392156863 0.250980392156863 0.250980392156863 1" />
      </material>
    </visual>
    <collision>
      <origin
        xyz="0 0 0"
        rpy="0 0 0" />
      <geometry>
        <mesh
          filename="meshes/thumb_fingerpad.STL" />
      </geometry>
    </collision>
  </link>
  <joint
    name="thumb_fingerpad_joint"
    type="fixed">
    <origin
      xyz="0.034 -0.00499999999999983 -0.0398000000000015"
      rpy="1.80666825946076 -0.379498136323909 0.503100653479423" />
    <parent
      link="thumb_link_3" />
    <child
      link="thumb_fingerpad" />
    <axis
      xyz="0 0 0" />
  </joint>
  <link
    name="middle_link_0">
    <inertial>
      <origin
        xyz="0.0536195114634704 -2.42606474652085E-10 0.0270490836849533"
        rpy="0 0 0" />
      <mass
        value="0.0268394050979217" />
      <inertia
        ixx="3.45036780154115E-06"
        ixy="-8.67763893561692E-13"
        ixz="-7.1407245484483E-07"
        iyy="6.44607010084784E-06"
        iyz="-5.58890421158203E-13"
        izz="4.66534332329056E-06" />
    </inertial>
    <visual>
      <origin
        xyz="0 0 0"
        rpy="0 0 0" />
      <geometry>
        <mesh
          filename="meshes/middle_link_0.STL" />
      </geometry>
      <material
        name="">
        <color
          rgba="0.250980392156863 0.250980392156863 0.250980392156863 1" />
      </material>
    </visual>
    <collision>
      <origin
        xyz="0 0 0"
        rpy="0 0 0" />
      <geometry>
        <mesh
          filename="meshes/middle_link_0.STL" />
      </geometry>
    </collision>
  </link>
  <joint
    name="middle_joint_0"
    type="revolute">
    <origin
      xyz="-0.025 0 0"
      rpy="0 0 -3.1416" />
    <parent
      link="base_link" />
    <child
      link="middle_link_0" />
    <axis
      xyz="0 0 1" />
    <limit
      lower="-0.3"
      upper="0.3"
      effort="0"
      velocity="0" />
  </joint>
  <link
    name="middle_link_1">
    <inertial>
      <origin
        xyz="0.0364928103809858 -0.00525061406363376 0.000176615436499411"
        rpy="0 0 0" />
      <mass
        value="0.0329000270028115" />
      <inertia
        ixx="4.78314507668699E-06"
        ixy="1.40869805443595E-07"
        ixz="-3.79420138219543E-14"
        iyy="3.23635026567844E-06"
        iyz="-4.28547769247267E-08"
        izz="3.4883400552915E-06" />
    </inertial>
    <visual>
      <origin
        xyz="0 0 0"
        rpy="0 0 0" />
      <geometry>
        <mesh
          filename="meshes/middle_link_1.STL" />
      </geometry>
      <material
        name="">
        <color
          rgba="0.250980392156863 0.250980392156863 0.250980392156863 1" />
      </material>
    </visual>
    <collision>
      <origin
        xyz="0 0 0"
        rpy="0 0 0" />
      <geometry>
        <mesh
          filename="meshes/middle_link_1.STL" />
      </geometry>
    </collision>
  </link>
  <joint
    name="middle_joint_1"
    type="revolute">
    <origin
      xyz="0.067 0 0.046"
      rpy="1.5708 0 -1.5708" />
    <parent
      link="middle_link_0" />
    <child
      link="middle_link_1" />
    <axis
      xyz="0 0 1" />
    <limit
      lower="-0.17"
      upper="1.57"
      effort="0"
      velocity="0" />
  </joint>
  <link
    name="middle_link_2">
    <inertial>
      <origin
        xyz="0.0100768333002347 1.60817089965731E-13 -1.20249643575931E-12"
        rpy="0 0 0" />
      <mass
        value="0.00252674876938612" />
      <inertia
        ixx="5.37570168949986E-07"
        ixy="2.36907917971866E-18"
        ixz="-2.68578785473445E-17"
        iyy="5.77184540925891E-07"
        iyz="2.72607543983347E-18"
        izz="2.13320625554569E-07" />
    </inertial>
    <visual>
      <origin
        xyz="0 0 0"
        rpy="0 0 0" />
      <geometry>
        <mesh
          filename="meshes/middle_link_2.STL" />
      </geometry>
      <material
        name="">
        <color
          rgba="0.250980392156863 0.250980392156863 0.250980392156863 1" />
      </material>
    </visual>
    <collision>
      <origin
        xyz="0 0 0"
        rpy="0 0 0" />
      <geometry>
        <mesh
          filename="meshes/middle_link_2.STL" />
      </geometry>
    </collision>
  </link>
  <joint
    name="middle_joint_2"
    type="revolute">
    <origin
      xyz="0.0485 0 0"
      rpy="0 0 0" />
    <parent
      link="middle_link_1" />
    <child
      link="middle_link_2" />
    <axis
      xyz="0 0 1" />
    <limit
      lower="-0.1"
      upper="1.57"
      effort="0"
      velocity="0" />
  </joint>
  <link
    name="middle_fingerpad">
    <inertial>
      <origin
        xyz="-0.0109953455583793 0.0202016893674789 -0.00127026828443108"
        rpy="0 0 0" />
      <mass
        value="0.00332341020047785" />
      <inertia
        ixx="1.37247704515366E-06"
        ixy="4.5112827317268E-07"
        ixz="-4.1292536829662E-08"
        iyy="3.01929067803903E-07"
        iyz="1.28907614232009E-07"
        izz="1.57531612689999E-06" />
    </inertial>
    <visual>
      <origin
        xyz="0 0 0"
        rpy="0 0 0" />
      <geometry>
        <mesh
          filename="meshes/middle_fingerpad.STL" />
      </geometry>
      <material
        name="">
        <color
          rgba="0.250980392156863 0.250980392156863 0.250980392156863 1" />
      </material>
    </visual>
    <collision>
      <origin
        xyz="0 0 0"
        rpy="0 0 0" />
      <geometry>
        <mesh
          filename="meshes/middle_fingerpad.STL" />
      </geometry>
    </collision>
  </link>
  <joint
    name="middle_fingerpad_joint"
    type="fixed">
    <origin
      xyz="0.0302000000000001 0.00700000000000259 0.0669999999999999"
      rpy="-1.5707963267949 0 0" />
    <parent
      link="middle_link_2" />
    <child
      link="middle_fingerpad" />
    <axis
      xyz="0 0 0" />
  </joint>
</robot>